### [bt]: This is batchtools v0.9.15
### [bt]: Starting calculation of 1 jobs
### [bt]: Setting working directory to '/projects/genomic-ml/sub-quadratic-full-gradient-AUC-optimization/app'
### [bt]: Memory measurement disabled
### [bt]: Starting job [batchtools job.id=81]
### [bt]: Setting seed to 31950 ...
2021-10-21 11:50:17.386228: W tensorflow/stream_executor/platform/default/dso_loader.cc:64] Could not load dynamic library 'libcudart.so.11.0'; dlerror: libcudart.so.11.0: cannot open shared object file: No such file or directory; LD_LIBRARY_PATH: /packages/gcc-8.3.1/R/4.1.0/lib64/R/lib:/usr/local/lib64:/etc/alternatives/jre_openjdk/lib/amd64/server:/packages/gcc-8.3.1/R/4.1.0/lib64/R/lib:/usr/local/lib64:/etc/alternatives/jre_openjdk/lib/amd64/server:/packages/gcc-8.3.1/netcdf-c/4.7.4-opdm2fw/lib:/packages/libtiff/4.1.0/lib:/packages/gcc-8.3.1/geos/3.8.1-j7t4spf/lib:/packages/gcc-8.3.1/proj/7.1.0/lib:/packages/gdal/3.3.1/lib:/packages/gcc-8.3.1/R/4.1.0/lib64/R/lib
2021-10-21 11:50:17.386427: I tensorflow/stream_executor/cuda/cudart_stub.cc:29] Ignore above cudart dlerror if you do not have a GPU set up on your machine.
/home/krr387/.conda/envs/emacs1/lib/python3.7/site-packages/torchmetrics/utilities/prints.py:36: UserWarning: Metric `AUROC` will save all targets and predictions in buffer. For large datasets this may lead to large memory footprint.
  warnings.warn(*args, **kwargs)
/projects/genomic-ml/sub-quadratic-full-gradient-AUC-optimization/app/convolutional_NN.py:56: UserWarning: Anomaly Detection has been enabled. This mode will increase the runtime and should only be enabled for debugging.
  torch.autograd.detect_anomaly()
using device=cpu
use_subset=False
Downloading data from https://www.cs.toronto.edu/~kriz/cifar-10-python.tar.gz
Traceback (most recent call last):
  File "/home/krr387/.conda/envs/emacs1/lib/python3.7/urllib/request.py", line 1319, in do_open
    encode_chunked=req.has_header('Transfer-encoding'))
  File "/home/krr387/.conda/envs/emacs1/lib/python3.7/http/client.py", line 1252, in request
    self._send_request(method, url, body, headers, encode_chunked)
  File "/home/krr387/.conda/envs/emacs1/lib/python3.7/http/client.py", line 1298, in _send_request
    self.endheaders(body, encode_chunked=encode_chunked)
  File "/home/krr387/.conda/envs/emacs1/lib/python3.7/http/client.py", line 1247, in endheaders
    self._send_output(message_body, encode_chunked=encode_chunked)
  File "/home/krr387/.conda/envs/emacs1/lib/python3.7/http/client.py", line 1026, in _send_output
    self.send(msg)
  File "/home/krr387/.conda/envs/emacs1/lib/python3.7/http/client.py", line 966, in send
    self.connect()
  File "/home/krr387/.conda/envs/emacs1/lib/python3.7/http/client.py", line 1414, in connect
    super().connect()
  File "/home/krr387/.conda/envs/emacs1/lib/python3.7/http/client.py", line 938, in connect
    (self.host,self.port), self.timeout, self.source_address)
  File "/home/krr387/.conda/envs/emacs1/lib/python3.7/socket.py", line 728, in create_connection
    raise err
  File "/home/krr387/.conda/envs/emacs1/lib/python3.7/socket.py", line 716, in create_connection
    sock.connect(sa)
TimeoutError: [Errno 110] Connection timed out

During handling of the above exception, another exception occurred:

Traceback (most recent call last):
  File "/home/krr387/.conda/envs/emacs1/lib/python3.7/site-packages/keras/utils/data_utils.py", line 274, in get_file
    urlretrieve(origin, fpath, dl_progress)
  File "/home/krr387/.conda/envs/emacs1/lib/python3.7/site-packages/keras/utils/data_utils.py", line 82, in urlretrieve
    response = urlopen(url, data)
  File "/home/krr387/.conda/envs/emacs1/lib/python3.7/urllib/request.py", line 222, in urlopen
    return opener.open(url, data, timeout)
  File "/home/krr387/.conda/envs/emacs1/lib/python3.7/urllib/request.py", line 525, in open
    response = self._open(req, data)
  File "/home/krr387/.conda/envs/emacs1/lib/python3.7/urllib/request.py", line 543, in _open
    '_open', req)
  File "/home/krr387/.conda/envs/emacs1/lib/python3.7/urllib/request.py", line 503, in _call_chain
    result = func(*args)
  File "/home/krr387/.conda/envs/emacs1/lib/python3.7/urllib/request.py", line 1362, in https_open
    context=self._context, check_hostname=self._check_hostname)
  File "/home/krr387/.conda/envs/emacs1/lib/python3.7/urllib/request.py", line 1321, in do_open
    raise URLError(err)
urllib.error.URLError: <urlopen error [Errno 110] Connection timed out>

During handling of the above exception, another exception occurred:

Traceback (most recent call last):
  File "driver.py", line 4, in <module>
    train_classifier(*train_args)
  File "/projects/genomic-ml/sub-quadratic-full-gradient-AUC-optimization/app/convolutional_NN.py", line 65, in train_classifier
    SEED, use_subset, batch_size, imratio, dataset)
  File "/projects/genomic-ml/sub-quadratic-full-gradient-AUC-optimization/app/load_data.py", line 56, in load_data
    (train_data, train_label), (test_data, test_label) = eval(dataset + "()")
  File "<string>", line 1, in <module>
  File "/home/krr387/.conda/envs/emacs1/lib/python3.7/site-packages/libauc/datasets/cifar.py", line 8, in CIFAR10
    (train_data, train_label), (test_data, test_label) = tf.keras.datasets.cifar10.load_data()
  File "/home/krr387/.conda/envs/emacs1/lib/python3.7/site-packages/keras/datasets/cifar10.py", line 84, in load_data
    '6d958be074577803d12ecdefd02955f39262c83c16fe9348329d7fe0b5c001ce')
  File "/home/krr387/.conda/envs/emacs1/lib/python3.7/site-packages/keras/utils/data_utils.py", line 278, in get_file
    raise Exception(error_msg.format(origin, e.errno, e.reason))
Exception: URL fetch failure on https://www.cs.toronto.edu/~kriz/cifar-10-python.tar.gz: None -- [Errno 110] Connection timed out
Error in (function (batch_size, imratio, loss_name, lr, dataset, model,  : 
  error code 1

### [bt]: Job terminated with an exception [batchtools job.id=81]
### [bt]: Calculation finished!
